#!/bin/bash
#SBATCH --job-name=data-proc
#SBATCH --partition=gpu-a40
#SBATCH --account=cse
#SBATCH --nodes=1
#SBATCH --cpus-per-task=8
#SBATCH --mem=32G
#SBATCH --gres=gpu:1
#SBATCH --time=11:00:00 
#SBATCH --mail-type=ALL
#SBATCH --mail-user=tjung2@uw.edu

# I use source to initialize conda into the right environment.
cat $0
echo "--------------------"

source ~/.bashrc
conda activate ckl

python run.py --config configs/wmt/training/t5_baseline_yearly.json--------------------
Traceback (most recent call last):
  File "/mmfs1/gscratch/ark/tjung2/miniconda3/envs/ckl/lib/python3.8/site-packages/wandb/sdk/wandb_init.py", line 1040, in init
    wi.setup(kwargs)
  File "/mmfs1/gscratch/ark/tjung2/miniconda3/envs/ckl/lib/python3.8/site-packages/wandb/sdk/wandb_init.py", line 151, in setup
    self._wl = wandb_setup.setup()
  File "/mmfs1/gscratch/ark/tjung2/miniconda3/envs/ckl/lib/python3.8/site-packages/wandb/sdk/wandb_setup.py", line 320, in setup
    ret = _setup(settings=settings)
  File "/mmfs1/gscratch/ark/tjung2/miniconda3/envs/ckl/lib/python3.8/site-packages/wandb/sdk/wandb_setup.py", line 315, in _setup
    wl = _WandbSetup(settings=settings)
  File "/mmfs1/gscratch/ark/tjung2/miniconda3/envs/ckl/lib/python3.8/site-packages/wandb/sdk/wandb_setup.py", line 301, in __init__
    _WandbSetup._instance = _WandbSetup__WandbSetup(settings=settings, pid=pid)
  File "/mmfs1/gscratch/ark/tjung2/miniconda3/envs/ckl/lib/python3.8/site-packages/wandb/sdk/wandb_setup.py", line 114, in __init__
    self._setup()
  File "/mmfs1/gscratch/ark/tjung2/miniconda3/envs/ckl/lib/python3.8/site-packages/wandb/sdk/wandb_setup.py", line 242, in _setup
    self._setup_manager()
  File "/mmfs1/gscratch/ark/tjung2/miniconda3/envs/ckl/lib/python3.8/site-packages/wandb/sdk/wandb_setup.py", line 273, in _setup_manager
    self._manager = wandb_manager._Manager(
  File "/mmfs1/gscratch/ark/tjung2/miniconda3/envs/ckl/lib/python3.8/site-packages/wandb/sdk/wandb_manager.py", line 106, in __init__
    self._service.start()
  File "/mmfs1/gscratch/ark/tjung2/miniconda3/envs/ckl/lib/python3.8/site-packages/wandb/sdk/service/service.py", line 106, in start
    self._launch_server()
  File "/mmfs1/gscratch/ark/tjung2/miniconda3/envs/ckl/lib/python3.8/site-packages/wandb/sdk/service/service.py", line 102, in _launch_server
    assert ports_found
AssertionError
wandb: ERROR Abnormal program exit
Traceback (most recent call last):
  File "/mmfs1/gscratch/ark/tjung2/miniconda3/envs/ckl/lib/python3.8/site-packages/wandb/sdk/wandb_init.py", line 1040, in init
    wi.setup(kwargs)
  File "/mmfs1/gscratch/ark/tjung2/miniconda3/envs/ckl/lib/python3.8/site-packages/wandb/sdk/wandb_init.py", line 151, in setup
    self._wl = wandb_setup.setup()
  File "/mmfs1/gscratch/ark/tjung2/miniconda3/envs/ckl/lib/python3.8/site-packages/wandb/sdk/wandb_setup.py", line 320, in setup
    ret = _setup(settings=settings)
  File "/mmfs1/gscratch/ark/tjung2/miniconda3/envs/ckl/lib/python3.8/site-packages/wandb/sdk/wandb_setup.py", line 315, in _setup
    wl = _WandbSetup(settings=settings)
  File "/mmfs1/gscratch/ark/tjung2/miniconda3/envs/ckl/lib/python3.8/site-packages/wandb/sdk/wandb_setup.py", line 301, in __init__
    _WandbSetup._instance = _WandbSetup__WandbSetup(settings=settings, pid=pid)
  File "/mmfs1/gscratch/ark/tjung2/miniconda3/envs/ckl/lib/python3.8/site-packages/wandb/sdk/wandb_setup.py", line 114, in __init__
    self._setup()
  File "/mmfs1/gscratch/ark/tjung2/miniconda3/envs/ckl/lib/python3.8/site-packages/wandb/sdk/wandb_setup.py", line 242, in _setup
    self._setup_manager()
  File "/mmfs1/gscratch/ark/tjung2/miniconda3/envs/ckl/lib/python3.8/site-packages/wandb/sdk/wandb_setup.py", line 273, in _setup_manager
    self._manager = wandb_manager._Manager(
  File "/mmfs1/gscratch/ark/tjung2/miniconda3/envs/ckl/lib/python3.8/site-packages/wandb/sdk/wandb_manager.py", line 106, in __init__
    self._service.start()
  File "/mmfs1/gscratch/ark/tjung2/miniconda3/envs/ckl/lib/python3.8/site-packages/wandb/sdk/service/service.py", line 106, in start
    self._launch_server()
  File "/mmfs1/gscratch/ark/tjung2/miniconda3/envs/ckl/lib/python3.8/site-packages/wandb/sdk/service/service.py", line 102, in _launch_server
    assert ports_found
AssertionError

The above exception was the direct cause of the following exception:

Traceback (most recent call last):
  File "run.py", line 125, in <module>
    wandb.init(project=hparam.wandb_project, name=f"{hparam.method}_{args['dataset_version']}" , config=args, settings=wandb.Settings(start_method="fork"))
  File "/mmfs1/gscratch/ark/tjung2/miniconda3/envs/ckl/lib/python3.8/site-packages/wandb/sdk/wandb_init.py", line 1081, in init
    raise Exception("problem") from error_seen
Exception: problem
