#!/bin/bash
#SBATCH --job-name=data-proc
#SBATCH --partition=gpu-a40
#SBATCH --account=ark
#SBATCH --nodes=1
#SBATCH --cpus-per-task=8
#SBATCH --mem=32G
#SBATCH --gres=gpu:1
#SBATCH --time=04:59:00
#SBATCH --mail-type=ALL
#SBATCH --mail-user=tjung2@uw.edu

# I use source to initialize conda into the right environment.
cat $0
echo "--------------------"

source ~/.bashrc
conda activate ckl

python run.py --config configs/templama/training/t5_baseline_2010_prefixed_test.json
--------------------
Traceback (most recent call last):
  File "/mmfs1/gscratch/ark/tjung2/miniconda3/envs/ckl/lib/python3.8/site-packages/wandb/sdk/wandb_init.py", line 1040, in init
    wi.setup(kwargs)
  File "/mmfs1/gscratch/ark/tjung2/miniconda3/envs/ckl/lib/python3.8/site-packages/wandb/sdk/wandb_init.py", line 151, in setup
    self._wl = wandb_setup.setup()
  File "/mmfs1/gscratch/ark/tjung2/miniconda3/envs/ckl/lib/python3.8/site-packages/wandb/sdk/wandb_setup.py", line 320, in setup
    ret = _setup(settings=settings)
  File "/mmfs1/gscratch/ark/tjung2/miniconda3/envs/ckl/lib/python3.8/site-packages/wandb/sdk/wandb_setup.py", line 315, in _setup
    wl = _WandbSetup(settings=settings)
  File "/mmfs1/gscratch/ark/tjung2/miniconda3/envs/ckl/lib/python3.8/site-packages/wandb/sdk/wandb_setup.py", line 301, in __init__
    _WandbSetup._instance = _WandbSetup__WandbSetup(settings=settings, pid=pid)
  File "/mmfs1/gscratch/ark/tjung2/miniconda3/envs/ckl/lib/python3.8/site-packages/wandb/sdk/wandb_setup.py", line 114, in __init__
    self._setup()
  File "/mmfs1/gscratch/ark/tjung2/miniconda3/envs/ckl/lib/python3.8/site-packages/wandb/sdk/wandb_setup.py", line 242, in _setup
    self._setup_manager()
  File "/mmfs1/gscratch/ark/tjung2/miniconda3/envs/ckl/lib/python3.8/site-packages/wandb/sdk/wandb_setup.py", line 273, in _setup_manager
    self._manager = wandb_manager._Manager(
  File "/mmfs1/gscratch/ark/tjung2/miniconda3/envs/ckl/lib/python3.8/site-packages/wandb/sdk/wandb_manager.py", line 123, in __init__
    svc_iface._svc_connect(port=port)
  File "/mmfs1/gscratch/ark/tjung2/miniconda3/envs/ckl/lib/python3.8/site-packages/wandb/sdk/service/service_sock.py", line 31, in _svc_connect
    self._sock_client.connect(port=port)
  File "/mmfs1/gscratch/ark/tjung2/miniconda3/envs/ckl/lib/python3.8/site-packages/wandb/sdk/lib/sock_client.py", line 41, in connect
    s.connect(("localhost", port))
ConnectionRefusedError: [Errno 111] Connection refused
wandb: ERROR Abnormal program exit
Traceback (most recent call last):
  File "/mmfs1/gscratch/ark/tjung2/miniconda3/envs/ckl/lib/python3.8/site-packages/wandb/sdk/wandb_init.py", line 1040, in init
    wi.setup(kwargs)
  File "/mmfs1/gscratch/ark/tjung2/miniconda3/envs/ckl/lib/python3.8/site-packages/wandb/sdk/wandb_init.py", line 151, in setup
    self._wl = wandb_setup.setup()
  File "/mmfs1/gscratch/ark/tjung2/miniconda3/envs/ckl/lib/python3.8/site-packages/wandb/sdk/wandb_setup.py", line 320, in setup
    ret = _setup(settings=settings)
  File "/mmfs1/gscratch/ark/tjung2/miniconda3/envs/ckl/lib/python3.8/site-packages/wandb/sdk/wandb_setup.py", line 315, in _setup
    wl = _WandbSetup(settings=settings)
  File "/mmfs1/gscratch/ark/tjung2/miniconda3/envs/ckl/lib/python3.8/site-packages/wandb/sdk/wandb_setup.py", line 301, in __init__
    _WandbSetup._instance = _WandbSetup__WandbSetup(settings=settings, pid=pid)
  File "/mmfs1/gscratch/ark/tjung2/miniconda3/envs/ckl/lib/python3.8/site-packages/wandb/sdk/wandb_setup.py", line 114, in __init__
    self._setup()
  File "/mmfs1/gscratch/ark/tjung2/miniconda3/envs/ckl/lib/python3.8/site-packages/wandb/sdk/wandb_setup.py", line 242, in _setup
    self._setup_manager()
  File "/mmfs1/gscratch/ark/tjung2/miniconda3/envs/ckl/lib/python3.8/site-packages/wandb/sdk/wandb_setup.py", line 273, in _setup_manager
    self._manager = wandb_manager._Manager(
  File "/mmfs1/gscratch/ark/tjung2/miniconda3/envs/ckl/lib/python3.8/site-packages/wandb/sdk/wandb_manager.py", line 123, in __init__
    svc_iface._svc_connect(port=port)
  File "/mmfs1/gscratch/ark/tjung2/miniconda3/envs/ckl/lib/python3.8/site-packages/wandb/sdk/service/service_sock.py", line 31, in _svc_connect
    self._sock_client.connect(port=port)
  File "/mmfs1/gscratch/ark/tjung2/miniconda3/envs/ckl/lib/python3.8/site-packages/wandb/sdk/lib/sock_client.py", line 41, in connect
    s.connect(("localhost", port))
ConnectionRefusedError: [Errno 111] Connection refused

The above exception was the direct cause of the following exception:

Traceback (most recent call last):
  File "run.py", line 93, in <module>
    wandb.init(project=hparam.wandb_project, name=hparam.wandb_run_name, config=args)
  File "/mmfs1/gscratch/ark/tjung2/miniconda3/envs/ckl/lib/python3.8/site-packages/wandb/sdk/wandb_init.py", line 1081, in init
    raise Exception("problem") from error_seen
Exception: problem
