2022-08-11 18:04:10,877 INFO    MainThread:69616 [internal.py:wandb_internal():90] W&B internal server running at pid: 69616, started at: 2022-08-11 18:04:10.875347
2022-08-11 18:04:10,878 INFO    WriterThread:69616 [datastore.py:open_for_write():75] open: /mmfs1/gscratch/ark/tjung2/continual-knowledge-learning/wandb/run-20220811_180409-z6gyllak/run-z6gyllak.wandb
2022-08-11 18:04:10,880 DEBUG   SenderThread:69616 [sender.py:send():236] send: header
2022-08-11 18:04:10,881 DEBUG   SenderThread:69616 [sender.py:send():236] send: run
2022-08-11 18:04:10,885 INFO    SenderThread:69616 [sender.py:_maybe_setup_resume():493] checking resume status for None/temporal_questions/z6gyllak
2022-08-11 18:04:39,644 DEBUG   HandlerThread:69616 [handler.py:handle_request():140] handle_request: shutdown
2022-08-11 18:04:39,644 INFO    HandlerThread:69616 [handler.py:finish():806] shutting down handler
2022-08-11 18:04:39,883 INFO    WriterThread:69616 [datastore.py:close():279] close: /mmfs1/gscratch/ark/tjung2/continual-knowledge-learning/wandb/run-20220811_180409-z6gyllak/run-z6gyllak.wandb
2022-08-11 18:04:44,717 ERROR   SenderThread:69616 [retry.py:__call__():132] Retry attempt failed:
Traceback (most recent call last):
  File "/mmfs1/gscratch/ark/tjung2/miniconda3/envs/ckl/lib/python3.8/site-packages/urllib3/connectionpool.py", line 449, in _make_request
    six.raise_from(e, None)
  File "<string>", line 3, in raise_from
  File "/mmfs1/gscratch/ark/tjung2/miniconda3/envs/ckl/lib/python3.8/site-packages/urllib3/connectionpool.py", line 444, in _make_request
    httplib_response = conn.getresponse()
  File "/mmfs1/gscratch/ark/tjung2/miniconda3/envs/ckl/lib/python3.8/http/client.py", line 1348, in getresponse
    response.begin()
  File "/mmfs1/gscratch/ark/tjung2/miniconda3/envs/ckl/lib/python3.8/http/client.py", line 316, in begin
    version, status, reason = self._read_status()
  File "/mmfs1/gscratch/ark/tjung2/miniconda3/envs/ckl/lib/python3.8/http/client.py", line 277, in _read_status
    line = str(self.fp.readline(_MAXLINE + 1), "iso-8859-1")
  File "/mmfs1/gscratch/ark/tjung2/miniconda3/envs/ckl/lib/python3.8/socket.py", line 669, in readinto
    return self._sock.recv_into(b)
  File "/mmfs1/gscratch/ark/tjung2/miniconda3/envs/ckl/lib/python3.8/ssl.py", line 1241, in recv_into
    return self.read(nbytes, buffer)
  File "/mmfs1/gscratch/ark/tjung2/miniconda3/envs/ckl/lib/python3.8/ssl.py", line 1099, in read
    return self._sslobj.read(len, buffer)
socket.timeout: The read operation timed out

During handling of the above exception, another exception occurred:

Traceback (most recent call last):
  File "/mmfs1/gscratch/ark/tjung2/miniconda3/envs/ckl/lib/python3.8/site-packages/requests/adapters.py", line 489, in send
    resp = conn.urlopen(
  File "/mmfs1/gscratch/ark/tjung2/miniconda3/envs/ckl/lib/python3.8/site-packages/urllib3/connectionpool.py", line 787, in urlopen
    retries = retries.increment(
  File "/mmfs1/gscratch/ark/tjung2/miniconda3/envs/ckl/lib/python3.8/site-packages/urllib3/util/retry.py", line 550, in increment
    raise six.reraise(type(error), error, _stacktrace)
  File "/mmfs1/gscratch/ark/tjung2/miniconda3/envs/ckl/lib/python3.8/site-packages/urllib3/packages/six.py", line 770, in reraise
    raise value
  File "/mmfs1/gscratch/ark/tjung2/miniconda3/envs/ckl/lib/python3.8/site-packages/urllib3/connectionpool.py", line 703, in urlopen
    httplib_response = self._make_request(
  File "/mmfs1/gscratch/ark/tjung2/miniconda3/envs/ckl/lib/python3.8/site-packages/urllib3/connectionpool.py", line 451, in _make_request
    self._raise_timeout(err=e, url=url, timeout_value=read_timeout)
  File "/mmfs1/gscratch/ark/tjung2/miniconda3/envs/ckl/lib/python3.8/site-packages/urllib3/connectionpool.py", line 340, in _raise_timeout
    raise ReadTimeoutError(
urllib3.exceptions.ReadTimeoutError: HTTPSConnectionPool(host='api.wandb.ai', port=443): Read timed out. (read timeout=10)

During handling of the above exception, another exception occurred:

Traceback (most recent call last):
  File "/mmfs1/gscratch/ark/tjung2/miniconda3/envs/ckl/lib/python3.8/site-packages/wandb/sdk/lib/retry.py", line 108, in __call__
    result = self._call_fn(*args, **kwargs)
  File "/mmfs1/gscratch/ark/tjung2/miniconda3/envs/ckl/lib/python3.8/site-packages/wandb/sdk/internal/internal_api.py", line 158, in execute
    return self.client.execute(*args, **kwargs)
  File "/mmfs1/gscratch/ark/tjung2/miniconda3/envs/ckl/lib/python3.8/site-packages/wandb/vendor/gql-0.2.0/wandb_gql/client.py", line 52, in execute
    result = self._get_result(document, *args, **kwargs)
  File "/mmfs1/gscratch/ark/tjung2/miniconda3/envs/ckl/lib/python3.8/site-packages/wandb/vendor/gql-0.2.0/wandb_gql/client.py", line 60, in _get_result
    return self.transport.execute(document, *args, **kwargs)
  File "/mmfs1/gscratch/ark/tjung2/miniconda3/envs/ckl/lib/python3.8/site-packages/wandb/vendor/gql-0.2.0/wandb_gql/transport/requests.py", line 38, in execute
    request = requests.post(self.url, **post_args)
  File "/mmfs1/gscratch/ark/tjung2/miniconda3/envs/ckl/lib/python3.8/site-packages/requests/api.py", line 115, in post
    return request("post", url, data=data, json=json, **kwargs)
  File "/mmfs1/gscratch/ark/tjung2/miniconda3/envs/ckl/lib/python3.8/site-packages/requests/api.py", line 59, in request
    return session.request(method=method, url=url, **kwargs)
  File "/mmfs1/gscratch/ark/tjung2/miniconda3/envs/ckl/lib/python3.8/site-packages/requests/sessions.py", line 587, in request
    resp = self.send(prep, **send_kwargs)
  File "/mmfs1/gscratch/ark/tjung2/miniconda3/envs/ckl/lib/python3.8/site-packages/requests/sessions.py", line 701, in send
    r = adapter.send(request, **kwargs)
  File "/mmfs1/gscratch/ark/tjung2/miniconda3/envs/ckl/lib/python3.8/site-packages/requests/adapters.py", line 578, in send
    raise ReadTimeout(e, request=request)
requests.exceptions.ReadTimeout: HTTPSConnectionPool(host='api.wandb.ai', port=443): Read timed out. (read timeout=10)
2022-08-11 18:05:37,581 ERROR   SenderThread:69616 [internal_api.py:execute():161] 500 response executing GraphQL.
2022-08-11 18:05:37,581 ERROR   SenderThread:69616 [internal_api.py:execute():162] {"errors":[{"message":"internal database error","path":["upsertBucket"]}],"data":{"upsertBucket":null}}
2022-08-11 18:06:12,719 INFO    SenderThread:69616 [dir_watcher.py:__init__():216] watching files in: /mmfs1/gscratch/ark/tjung2/continual-knowledge-learning/wandb/run-20220811_180409-z6gyllak/files
2022-08-11 18:06:12,719 INFO    SenderThread:69616 [sender.py:_start_run_threads():815] run started: z6gyllak with start time 1660266249
2022-08-11 18:06:12,719 INFO    SenderThread:69616 [sender.py:finish():1114] shutting down sender
2022-08-11 18:06:12,719 INFO    SenderThread:69616 [dir_watcher.py:finish():353] shutting down directory watcher
2022-08-11 18:06:13,719 INFO    SenderThread:69616 [dir_watcher.py:finish():383] scan: /mmfs1/gscratch/ark/tjung2/continual-knowledge-learning/wandb/run-20220811_180409-z6gyllak/files
2022-08-11 18:06:13,719 INFO    SenderThread:69616 [dir_watcher.py:finish():397] scan save: /mmfs1/gscratch/ark/tjung2/continual-knowledge-learning/wandb/run-20220811_180409-z6gyllak/files/config.yaml config.yaml
2022-08-11 18:06:13,719 INFO    SenderThread:69616 [file_pusher.py:finish():171] shutting down file pusher
2022-08-11 18:06:13,720 INFO    SenderThread:69616 [file_pusher.py:join():176] waiting for file pusher
2022-08-11 18:06:14,138 INFO    Thread-9  :69616 [upload_job.py:push():138] Uploaded file /mmfs1/gscratch/ark/tjung2/continual-knowledge-learning/wandb/run-20220811_180409-z6gyllak/files/config.yaml
2022-08-11 18:06:14,821 INFO    MainThread:69616 [internal.py:handle_exit():80] Internal process exited
